Workbook

Sheet Dashboard
A1: DASHBOARD COMERCIAL 2026
A3: Mês corrente: | B3: =Parâmetros!B7 | C3: Dias úteis: | D3: =Parâmetros!B4 & " / " & Parâmetros!B5
A5: META DO MÊS | D5: REALIZADO MÊS | G5: % ATINGIDO MÊS | J5: PROJEÇÃO MÊS
A6: =INDEX(Metas!B:M,19,Parâmetros!B3) | D6: =INDEX('Realizado por Hunter'!B:M,20,Parâmetros!B3) | G6: =IFERROR(INDEX('Realizado por Hunter'!B:M,20,Parâmetros!B3)/INDEX(Metas!B:M,19,Parâmetros!B3),0) | J6: =IFERROR(INDEX('Realizado por Hunter'!B:M,20,Parâmetros!B3)/Parâmetros!B4*Parâmetros!B5,0)
A9: META ACUM. ANO | D9: REALIZADO ACUM. | G9: % ATINGIDO ACUM. | J9: META TOTAL ANO
A10: =IFERROR(SUM(OFFSET(Metas!B19,0,0,1,Parâmetros!B3)),0) | D10: =IFERROR(SUM(OFFSET('Realizado por Hunter'!B20,0,0,1,Parâmetros!B3)),0) | G10: =IFERROR(SUM(OFFSET('Realizado por Hunter'!B20,0,0,1,Parâmetros!B3))/SUM(OFFSET(Metas!B19,0,0,1,Parâmetros!B3)),0) | J10: =Metas!N19
A78: ℹ Use a aba 'Parâmetros' para alterar mês corrente e dias úteis. Os indicadores se recalculam automaticamente. Para alimentar 'Parceiros', preencha a coluna C da aba 'Base de Dados'.

Sheet Meta vs Realizado
A1: META vs REALIZADO 2026 — COM PROJEÇÃO
A3: MÊS | B3: META | C3: REALIZADO | D3: % ATINGIDO | E3: ACUM. META | F3: ACUM. REALIZADO | G3: % ACUM.
A4: JAN | B4: =Metas!B19 | C4: ='Realizado por Hunter'!B20 | D4: =IFERROR(C4/B4,0) | E4: =B4 | F4: =C4 | G4: =IFERROR(F4/E4,0)
A5: FEV | B5: =Metas!C19 | C5: ='Realizado por Hunter'!C20 | D5: =IFERROR(C5/B5,0) | E5: =E4+B5 | F5: =F4+C5 | G5: =IFERROR(F5/E5,0)
A6: MAR | B6: =Metas!D19 | C6: ='Realizado por Hunter'!D20 | D6: =IFERROR(C6/B6,0) | E6: =E5+B6 | F6: =F5+C6 | G6: =IFERROR(F6/E6,0)
A7: ABR | B7: =Metas!E19 | C7: ='Realizado por Hunter'!E20 | D7: =IFERROR(C7/B7,0) | E7: =E6+B7 | F7: =F6+C7 | G7: =IFERROR(F7/E7,0)
A8: MAI | B8: =Metas!F19 | C8: ='Realizado por Hunter'!F20 | D8: =IFERROR(C8/B8,0) | E8: =E7+B8 | F8: =F7+C8 | G8: =IFERROR(F8/E8,0)
A9: JUN | B9: =Metas!G19 | C9: ='Realizado por Hunter'!G20 | D9: =IFERROR(C9/B9,0) | E9: =E8+B9 | F9: =F8+C9 | G9: =IFERROR(F9/E9,0)
A10: JUL | B10: =Metas!H19 | C10: ='Realizado por Hunter'!H20 | D10: =IFERROR(C10/B10,0) | E10: =E9+B10 | F10: =F9+C10 | G10: =IFERROR(F10/E10,0)
A11: AGO | B11: =Metas!I19 | C11: ='Realizado por Hunter'!I20 | D11: =IFERROR(C11/B11,0) | E11: =E10+B11 | F11: =F10+C11 | G11: =IFERROR(F11/E11,0)
A12: SET | B12: =Metas!J19 | C12: ='Realizado por Hunter'!J20 | D12: =IFERROR(C12/B12,0) | E12: =E11+B12 | F12: =F11+C12 | G12: =IFERROR(F12/E12,0)
A13: OUT | B13: =Metas!K19 | C13: ='Realizado por Hunter'!K20 | D13: =IFERROR(C13/B13,0) | E13: =E12+B13 | F13: =F12+C13 | G13: =IFERROR(F13/E13,0)
A14: NOV | B14: =Metas!L19 | C14: ='Realizado por Hunter'!L20 | D14: =IFERROR(C14/B14,0) | E14: =E13+B14 | F14: =F13+C14 | G14: =IFERROR(F14/E14,0)
A15: DEZ | B15: =Metas!M19 | C15: ='Realizado por Hunter'!M20 | D15: =IFERROR(C15/B15,0) | E15: =E14+B15 | F15: =F14+C15 | G15: =IFERROR(F15/E15,0)
A16: TOTAL ANO | B16: =SUM(B4:B15) | C16: =SUM(C4:C15) | D16: =IFERROR(C16/B16,0)
A19: PROJEÇÃO DO MÊS CORRENTE
A20: Mês de referência | B20: =Parâmetros!B7
A21: Meta do mês (R$) | B21: =INDEX(B4:B15,Parâmetros!B3)
A22: Realizado até hoje (R$) | B22: =INDEX(C4:C15,Parâmetros!B3)
A23: % Atingido até hoje | B23: =IFERROR(B22/B21,0)
A24: Dias úteis decorridos | B24: =Parâmetros!B4
A25: Dias úteis no mês | B25: =Parâmetros!B5
A26: Projeção fim de mês (R$) | B26: =IFERROR(B22/B24*B25,0)
A27: Gap p/ meta (R$) | B27: =B26-B21
A28: % Projetado da meta | B28: =IFERROR(B26/B21,0)

Sheet Hunter - Meta vs Real
A1: META vs REALIZADO POR HUNTER (Mês corrente)
A3: HUNTER | B3: PRAÇA | C3: META MÊS | D3: REALIZADO MÊS | E3: % ATING. MÊS | F3: META ACUM. | G3: REAL. ACUM. | H3: % ATING. ACUM. | I3: PROJEÇÃO MÊS
A4: ANDERSON | B4: Fortaleza | C4: =IFERROR(INDEX(Metas!B:M,MATCH(A4,Metas!A:A,0),Parâmetros!B3),0) | D4: =IFERROR(INDEX('Realizado por Hunter'!B:M,MATCH(A4,'Realizado por Hunter'!A:A,0),Parâmetros!B3),0) | E4: =IFERROR(D4/C4,0) | F4: =IFERROR(SUM(OFFSET(Metas!A1,MATCH(A4,Metas!A:A,0)-1,1,1,Parâmetros!B3)),0) | G4: =IFERROR(SUM(OFFSET('Realizado por Hunter'!A1,MATCH(A4,'Realizado por Hunter'!A:A,0)-1,1,1,Parâmetros!B3)),0) | H4: =IFERROR(G4/F4,0) | I4: =IFERROR(D4/Parâmetros!B4*Parâmetros!B5,0)
A5: ARTHUR | B5: Matriz | C5: =IFERROR(INDEX(Metas!B:M,MATCH(A5,Metas!A:A,0),Parâmetros!B3),0) | D5: =IFERROR(INDEX('Realizado por Hunter'!B:M,MATCH(A5,'Realizado por Hunter'!A:A,0),Parâmetros!B3),0) | E5: =IFERROR(D5/C5,0) | F5: =IFERROR(SUM(OFFSET(Metas!A1,MATCH(A5,Metas!A:A,0)-1,1,1,Parâmetros!B3)),0) | G5: =IFERROR(SUM(OFFSET('Realizado por Hunter'!A1,MATCH(A5,'Realizado por Hunter'!A:A,0)-1,1,1,Parâmetros!B3)),0) | H5: =IFERROR(G5/F5,0) | I5: =IFERROR(D5/Parâmetros!B4*Parâmetros!B5,0)
A6: BRUNA | B6: São Paulo e Santos | C6: =IFERROR(INDEX(Metas!B:M,MATCH(A6,Metas!A:A,0),Parâmetros!B3),0) | D6: =IFERROR(INDEX('Realizado por Hunter'!B:M,MATCH(A6,'Realizado por Hunter'!A:A,0),Parâmetros!B3),0) | E6: =IFERROR(D6/C6,0) | F6: =IFERROR(SUM(OFFSET(Metas!A1,MATCH(A6,Metas!A:A,0)-1,1,1,Parâmetros!B3)),0) | G6: =IFERROR(SUM(OFFSET('Realizado por Hunter'!A1,MATCH(A6,'Realizado por Hunter'!A:A,0)-1,1,1,Parâmetros!B3)),0) | H6: =IFERROR(G6/F6,0) | I6: =IFERROR(D6/Parâmetros!B4*Parâmetros!B5,0)
A7: CINTHIA | B7: Fortaleza | C7: =IFERROR(INDEX(Metas!B:M,MATCH(A7,Metas!A:A,0),Parâmetros!B3),0) | D7: =IFERROR(INDEX('Realizado por Hunter'!B:M,MATCH(A7,'Realizado por Hunter'!A:A,0),Parâmetros!B3),0) | E7: =IFERROR(D7/C7,0) | F7: =IFERROR(SUM(OFFSET(Metas!A1,MATCH(A7,Metas!A:A,0)-1,1,1,Parâmetros!B3)),0) | G7: =IFERROR(SUM(OFFSET('Realizado por Hunter'!A1,MATCH(A7,'Realizado por Hunter'!A:A,0)-1,1,1,Parâmetros!B3)),0) | H7: =IFERROR(G7/F7,0) | I7: =IFERROR(D7/Parâmetros!B4*Parâmetros!B5,0)
A8: DIMAS | B8: Teresina e Mato Grosso do Sul | C8: =IFERROR(INDEX(Metas!B:M,MATCH(A8,Metas!A:A,0),Parâmetros!B3),0) | D8: =IFERROR(INDEX('Realizado por Hunter'!B:M,MATCH(A8,'Realizado por Hunter'!A:A,0),Parâmetros!B3),0) | E8: =IFERROR(D8/C8,0) | F8: =IFERROR(SUM(OFFSET(Metas!A1,MATCH(A8,Metas!A:A,0)-1,1,1,Parâmetros!B3)),0) | G8: =IFERROR(SUM(OFFSET('Realizado por Hunter'!A1,MATCH(A8,'Realizado por Hunter'!A:A,0)-1,1,1,Parâmetros!B3)),0) | H8: =IFERROR(G8/F8,0) | I8: =IFERROR(D8/Parâmetros!B4*Parâmetros!B5,0)
A9: FORTALEZA 2 | B9: Fortaleza | C9: =IFERROR(INDEX(Metas!B:M,MATCH(A9,Metas!A:A,0),Parâmetros!B3),0) | D9: =IFERROR(INDEX('Realizado por Hunter'!B:M,MATCH(A9,'Realizado por Hunter'!A:A,0),Parâmetros!B3),0) | E9: =IFERROR(D9/C9,0) | F9: =IFERROR(SUM(OFFSET(Metas!A1,MATCH(A9,Metas!A:A,0)-1,1,1,Parâmetros!B3)),0) | G9: =IFERROR(SUM(OFFSET('Realizado por Hunter'!A1,MATCH(A9,'Realizado por Hunter'!A:A,0)-1,1,1,Parâmetros!B3)),0) | H9: =IFERROR(G9/F9,0) | I9: =IFERROR(D9/Parâmetros!B4*Parâmetros!B5,0)
A10: HEITOR | B10: Campinas | C10: =IFERROR(INDEX(Metas!B:M,MATCH(A10,Metas!A:A,0),Parâmetros!B3),0) | D10: =IFERROR(INDEX('Realizado por Hunter'!B:M,MATCH(A10,'Realizado por Hunter'!A:A,0),Parâmetros!B3),0) | E10: =IFERROR(D10/C10,0) | F10: =IFERROR(SUM(OFFSET(Metas!A1,MATCH(A10,Metas!A:A,0)-1,1,1,Parâmetros!B3)),0) | G10: =IFERROR(SUM(OFFSET('Realizado por Hunter'!A1,MATCH(A10,'Realizado por Hunter'!A:A,0)-1,1,1,Parâmetros!B3)),0) | H10: =IFERROR(G10/F10,0) | I10: =IFERROR(D10/Parâmetros!B4*Parâmetros!B5,0)
A11: HUDSON | B11: São Paulo - Matriz | C11: =IFERROR(INDEX(Metas!B:M,MATCH(A11,Metas!A:A,0),Parâmetros!B3),0) | D11: =IFERROR(INDEX('Realizado por Hunter'!B:M,MATCH(A11,'Realizado por Hunter'!A:A,0),Parâmetros!B3),0) | E11: =IFERROR(D11/C11,0) | F11: =IFERROR(SUM(OFFSET(Metas!A1,MATCH(A11,Metas!A:A,0)-1,1,1,Parâmetros!B3)),0) | G11: =IFERROR(SUM(OFFSET('Realizado por Hunter'!A1,MATCH(A11,'Realizado por Hunter'!A:A,0)-1,1,1,Parâmetros!B3)),0) | H11: =IFERROR(G11/F11,0) | I11: =IFERROR(D11/Parâmetros!B4*Parâmetros!B5,0)
A12: KATARINI | B12: Recife | C12: =IFERROR(INDEX(Metas!B:M,MATCH(A12,Metas!A:A,0),Parâmetros!B3),0) | D12: =IFERROR(INDEX('Realizado por Hunter'!B:M,MATCH(A12,'Realizado por Hunter'!A:A,0),Parâmetros!B3),0) | E12: =IFERROR(D12/C12,0) | F12: =IFERROR(SUM(OFFSET(Metas!A1,MATCH(A12,Metas!A:A,0)-1,1,1,Parâmetros!B3)),0) | G12: =IFERROR(SUM(OFFSET('Realizado por Hunter'!A1,MATCH(A12,'Realizado por Hunter'!A:A,0)-1,1,1,Parâmetros!B3)),0) | H12: =IFERROR(G12/F12,0) | I12: =IFERROR(D12/Parâmetros!B4*Parâmetros!B5,0)
A13: LEANDRO | B13: Marília e região | C13: =IFERROR(INDEX(Metas!B:M,MATCH(A13,Metas!A:A,0),Parâmetros!B3),0) | D13: =IFERROR(INDEX('Realizado por Hunter'!B:M,MATCH(A13,'Realizado por Hunter'!A:A,0),Parâmetros!B3),0) | E13: =IFERROR(D13/C13,0) | F13: =IFERROR(SUM(OFFSET(Metas!A1,MATCH(A13,Metas!A:A,0)-1,1,1,Parâmetros!B3)),0) | G13: =IFERROR(SUM(OFFSET('Realizado por Hunter'!A1,MATCH(A13,'Realizado por Hunter'!A:A,0)-1,1,1,Parâmetros!B3)),0) | H13: =IFERROR(G13/F13,0) | I13: =IFERROR(D13/Parâmetros!B4*Parâmetros!B5,0)
A14: NATHALIA | B14: São José do Rio Preto | C14: =IFERROR(INDEX(Metas!B:M,MATCH(A14,Metas!A:A,0),Parâmetros!B3),0) | D14: =IFERROR(INDEX('Realizado por Hunter'!B:M,MATCH(A14,'Realizado por Hunter'!A:A,0),Parâmetros!B3),0) | E14: =IFERROR(D14/C14,0) | F14: =IFERROR(SUM(OFFSET(Metas!A1,MATCH(A14,Metas!A:A,0)-1,1,1,Parâmetros!B3)),0) | G14: =IFERROR(SUM(OFFSET('Realizado por Hunter'!A1,MATCH(A14,'Realizado por Hunter'!A:A,0)-1,1,1,Parâmetros!B3)),0) | H14: =IFERROR(G14/F14,0) | I14: =IFERROR(D14/Parâmetros!B4*Parâmetros!B5,0)
A15: ORLANDO | B15: São Paulo - Matriz | C15: =IFERROR(INDEX(Metas!B:M,MATCH(A15,Metas!A:A,0),Parâmetros!B3),0) | D15: =IFERROR(INDEX('Realizado por Hunter'!B:M,MATCH(A15,'Realizado por Hunter'!A:A,0),Parâmetros!B3),0) | E15: =IFERROR(D15/C15,0) | F15: =IFERROR(SUM(OFFSET(Metas!A1,MATCH(A15,Metas!A:A,0)-1,1,1,Parâmetros!B3)),0) | G15: =IFERROR(SUM(OFFSET('Realizado por Hunter'!A1,MATCH(A15,'Realizado por Hunter'!A:A,0)-1,1,1,Parâmetros!B3)),0) | H15: =IFERROR(G15/F15,0) | I15: =IFERROR(D15/Parâmetros!B4*Parâmetros!B5,0)
A16: PIAUI 2 | B16: Teresina | C16: =IFERROR(INDEX(Metas!B:M,MATCH(A16,Metas!A:A,0),Parâmetros!B3),0) | D16: =IFERROR(INDEX('Realizado por Hunter'!B:M,MATCH(A16,'Realizado por Hunter'!A:A,0),Parâmetros!B3),0) | E16: =IFERROR(D16/C16,0) | F16: =IFERROR(SUM(OFFSET(Metas!A1,MATCH(A16,Metas!A:A,0)-1,1,1,Parâmetros!B3)),0) | G16: =IFERROR(SUM(OFFSET('Realizado por Hunter'!A1,MATCH(A16,'Realizado por Hunter'!A:A,0)-1,1,1,Parâmetros!B3)),0) | H16: =IFERROR(G16/F16,0) | I16: =IFERROR(D16/Parâmetros!B4*Parâmetros!B5,0)
A17: RAUL | B17: São José dos Campos e ABC | C17: =IFERROR(INDEX(Metas!B:M,MATCH(A17,Metas!A:A,0),Parâmetros!B3),0) | D17: =IFERROR(INDEX('Realizado por Hunter'!B:M,MATCH(A17,'Realizado por Hunter'!A:A,0),Parâmetros!B3),0) | E17: =IFERROR(D17/C17,0) | F17: =IFERROR(SUM(OFFSET(Metas!A1,MATCH(A17,Metas!A:A,0)-1,1,1,Parâmetros!B3)),0) | G17: =IFERROR(SUM(OFFSET('Realizado por Hunter'!A1,MATCH(A17,'Realizado por Hunter'!A:A,0)-1,1,1,Parâmetros!B3)),0) | H17: =IFERROR(G17/F17,0) | I17: =IFERROR(D17/Parâmetros!B4*Parâmetros!B5,0)
A18: SILAS | B18: Fortaleza | C18: =IFERROR(INDEX(Metas!B:M,MATCH(A18,Metas!A:A,0),Parâmetros!B3),0) | D18: =IFERROR(INDEX('Realizado por Hunter'!B:M,MATCH(A18,'Realizado por Hunter'!A:A,0),Parâmetros!B3),0) | E18: =IFERROR(D18/C18,0) | F18: =IFERROR(SUM(OFFSET(Metas!A1,MATCH(A18,Metas!A:A,0)-1,1,1,Parâmetros!B3)),0) | G18: =IFERROR(SUM(OFFSET('Realizado por Hunter'!A1,MATCH(A18,'Realizado por Hunter'!A:A,0)-1,1,1,Parâmetros!B3)),0) | H18: =IFERROR(G18/F18,0) | I18: =IFERROR(D18/Parâmetros!B4*Parâmetros!B5,0)
A19: THIAGO | B19: Recife | C19: =IFERROR(INDEX(Metas!B:M,MATCH(A19,Metas!A:A,0),Parâmetros!B3),0) | D19: =IFERROR(INDEX('Realizado por Hunter'!B:M,MATCH(A19,'Realizado por Hunter'!A:A,0),Parâmetros!B3),0) | E19: =IFERROR(D19/C19,0) | F19: =IFERROR(SUM(OFFSET(Metas!A1,MATCH(A19,Metas!A:A,0)-1,1,1,Parâmetros!B3)),0) | G19: =IFERROR(SUM(OFFSET('Realizado por Hunter'!A1,MATCH(A19,'Realizado por Hunter'!A:A,0)-1,1,1,Parâmetros!B3)),0) | H19: =IFERROR(G19/F19,0) | I19: =IFERROR(D19/Parâmetros!B4*Parâmetros!B5,0)
A20: TOTAL | C20: =SUM(C4:C19) | D20: =SUM(D4:D19) | E20: =IFERROR(D20/C20,0) | F20: =SUM(F4:F19) | G20: =SUM(G4:G19) | H20: =IFERROR(G20/F20,0) | I20: =SUM(I4:I19)

Sheet Praças
A1: RESULTADO POR PRAÇA
A3: PRAÇA | B3: META MÊS | C3: REALIZADO MÊS | D3: % ATING. MÊS | E3: REAL. ACUMULADO | F3: % ACUM.
A4: Campinas | B4: =SUMIFS('Hunter - Meta vs Real'!C:C,'Hunter - Meta vs Real'!B:B,A4) | C4: =SUMIFS('Hunter - Meta vs Real'!D:D,'Hunter - Meta vs Real'!B:B,A4) | D4: =IFERROR(C4/B4,0) | E4: =SUMIFS('Hunter - Meta vs Real'!G:G,'Hunter - Meta vs Real'!B:B,A4) | F4: =IFERROR(E4/SUMIFS('Hunter - Meta vs Real'!F:F,'Hunter - Meta vs Real'!B:B,A4),0)
A5: Fortaleza | B5: =SUMIFS('Hunter - Meta vs Real'!C:C,'Hunter - Meta vs Real'!B:B,A5) | C5: =SUMIFS('Hunter - Meta vs Real'!D:D,'Hunter - Meta vs Real'!B:B,A5) | D5: =IFERROR(C5/B5,0) | E5: =SUMIFS('Hunter - Meta vs Real'!G:G,'Hunter - Meta vs Real'!B:B,A5) | F5: =IFERROR(E5/SUMIFS('Hunter - Meta vs Real'!F:F,'Hunter - Meta vs Real'!B:B,A5),0)
A6: Marília e região | B6: =SUMIFS('Hunter - Meta vs Real'!C:C,'Hunter - Meta vs Real'!B:B,A6) | C6: =SUMIFS('Hunter - Meta vs Real'!D:D,'Hunter - Meta vs Real'!B:B,A6) | D6: =IFERROR(C6/B6,0) | E6: =SUMIFS('Hunter - Meta vs Real'!G:G,'Hunter - Meta vs Real'!B:B,A6) | F6: =IFERROR(E6/SUMIFS('Hunter - Meta vs Real'!F:F,'Hunter - Meta vs Real'!B:B,A6),0)
A7: Matriz | B7: =SUMIFS('Hunter - Meta vs Real'!C:C,'Hunter - Meta vs Real'!B:B,A7) | C7: =SUMIFS('Hunter - Meta vs Real'!D:D,'Hunter - Meta vs Real'!B:B,A7) | D7: =IFERROR(C7/B7,0) | E7: =SUMIFS('Hunter - Meta vs Real'!G:G,'Hunter - Meta vs Real'!B:B,A7) | F7: =IFERROR(E7/SUMIFS('Hunter - Meta vs Real'!F:F,'Hunter - Meta vs Real'!B:B,A7),0)
A8: Recife | B8: =SUMIFS('Hunter - Meta vs Real'!C:C,'Hunter - Meta vs Real'!B:B,A8) | C8: =SUMIFS('Hunter - Meta vs Real'!D:D,'Hunter - Meta vs Real'!B:B,A8) | D8: =IFERROR(C8/B8,0) | E8: =SUMIFS('Hunter - Meta vs Real'!G:G,'Hunter - Meta vs Real'!B:B,A8) | F8: =IFERROR(E8/SUMIFS('Hunter - Meta vs Real'!F:F,'Hunter - Meta vs Real'!B:B,A8),0)
A9: São José do Rio Preto | B9: =SUMIFS('Hunter - Meta vs Real'!C:C,'Hunter - Meta vs Real'!B:B,A9) | C9: =SUMIFS('Hunter - Meta vs Real'!D:D,'Hunter - Meta vs Real'!B:B,A9) | D9: =IFERROR(C9/B9,0) | E9: =SUMIFS('Hunter - Meta vs Real'!G:G,'Hunter - Meta vs Real'!B:B,A9) | F9: =IFERROR(E9/SUMIFS('Hunter - Meta vs Real'!F:F,'Hunter - Meta vs Real'!B:B,A9),0)
A10: São José dos Campos e ABC | B10: =SUMIFS('Hunter - Meta vs Real'!C:C,'Hunter - Meta vs Real'!B:B,A10) | C10: =SUMIFS('Hunter - Meta vs Real'!D:D,'Hunter - Meta vs Real'!B:B,A10) | D10: =IFERROR(C10/B10,0) | E10: =SUMIFS('Hunter - Meta vs Real'!G:G,'Hunter - Meta vs Real'!B:B,A10) | F10: =IFERROR(E10/SUMIFS('Hunter - Meta vs Real'!F:F,'Hunter - Meta vs Real'!B:B,A10),0)
A11: São Paulo - Matriz | B11: =SUMIFS('Hunter - Meta vs Real'!C:C,'Hunter - Meta vs Real'!B:B,A11) | C11: =SUMIFS('Hunter - Meta vs Real'!D:D,'Hunter - Meta vs Real'!B:B,A11) | D11: =IFERROR(C11/B11,0) | E11: =SUMIFS('Hunter - Meta vs Real'!G:G,'Hunter - Meta vs Real'!B:B,A11) | F11: =IFERROR(E11/SUMIFS('Hunter - Meta vs Real'!F:F,'Hunter - Meta vs Real'!B:B,A11),0)
A12: São Paulo e Santos | B12: =SUMIFS('Hunter - Meta vs Real'!C:C,'Hunter - Meta vs Real'!B:B,A12) | C12: =SUMIFS('Hunter - Meta vs Real'!D:D,'Hunter - Meta vs Real'!B:B,A12) | D12: =IFERROR(C12/B12,0) | E12: =SUMIFS('Hunter - Meta vs Real'!G:G,'Hunter - Meta vs Real'!B:B,A12) | F12: =IFERROR(E12/SUMIFS('Hunter - Meta vs Real'!F:F,'Hunter - Meta vs Real'!B:B,A12),0)
A13: Teresina | B13: =SUMIFS('Hunter - Meta vs Real'!C:C,'Hunter - Meta vs Real'!B:B,A13) | C13: =SUMIFS('Hunter - Meta vs Real'!D:D,'Hunter - Meta vs Real'!B:B,A13) | D13: =IFERROR(C13/B13,0) | E13: =SUMIFS('Hunter - Meta vs Real'!G:G,'Hunter - Meta vs Real'!B:B,A13) | F13: =IFERROR(E13/SUMIFS('Hunter - Meta vs Real'!F:F,'Hunter - Meta vs Real'!B:B,A13),0)
A14: Teresina e Mato Grosso do Sul | B14: =SUMIFS('Hunter - Meta vs Real'!C:C,'Hunter - Meta vs Real'!B:B,A14) | C14: =SUMIFS('Hunter - Meta vs Real'!D:D,'Hunter - Meta vs Real'!B:B,A14) | D14: =IFERROR(C14/B14,0) | E14: =SUMIFS('Hunter - Meta vs Real'!G:G,'Hunter - Meta vs Real'!B:B,A14) | F14: =IFERROR(E14/SUMIFS('Hunter - Meta vs Real'!F:F,'Hunter - Meta vs Real'!B:B,A14),0)
A15: TOTAL | B15: =SUM(B4:B14) | C15: =SUM(C4:C14) | D15: =IFERROR(C15/B15,0) | E15: =SUM(E4:E14) | F15: =IFERROR(E15/'Hunter - Meta vs Real'!F20,0)

Sheet Parceiros
A1: PARTICIPAÇÃO DE PARCEIROS
A3: ⚠ A coluna PARCEIRO foi adicionada na aba 'Base de Dados' (coluna C). Preencha-a para alimentar este painel automaticamente.
A5: PARCEIRO | B5: Nº NEGÓCIOS | C5: FATURAMENTO | D5: % PARTICIPAÇÃO | E5: TICKET MÉDIO
B6: =IF(A6="","",COUNTIFS('Base de Dados'!C:C,A6,'Base de Dados'!J:J,"ASSINADO")) | C6: =IF(A6="","",SUMIFS('Base de Dados'!I:I,'Base de Dados'!C:C,A6,'Base de Dados'!J:J,"ASSINADO")) | D6: =IFERROR(IF(A6="","",C6/SUM($C$6:$C$20)),0) | E6: =IFERROR(IF(A6="","",C6/B6),0)
B7: =IF(A7="","",COUNTIFS('Base de Dados'!C:C,A7,'Base de Dados'!J:J,"ASSINADO")) | C7: =IF(A7="","",SUMIFS('Base de Dados'!I:I,'Base de Dados'!C:C,A7,'Base de Dados'!J:J,"ASSINADO")) | D7: =IFERROR(IF(A7="","",C7/SUM($C$6:$C$20)),0) | E7: =IFERROR(IF(A7="","",C7/B7),0)
B8: =IF(A8="","",COUNTIFS('Base de Dados'!C:C,A8,'Base de Dados'!J:J,"ASSINADO")) | C8: =IF(A8="","",SUMIFS('Base de Dados'!I:I,'Base de Dados'!C:C,A8,'Base de Dados'!J:J,"ASSINADO")) | D8: =IFERROR(IF(A8="","",C8/SUM($C$6:$C$20)),0) | E8: =IFERROR(IF(A8="","",C8/B8),0)
B9: =IF(A9="","",COUNTIFS('Base de Dados'!C:C,A9,'Base de Dados'!J:J,"ASSINADO")) | C9: =IF(A9="","",SUMIFS('Base de Dados'!I:I,'Base de Dados'!C:C,A9,'Base de Dados'!J:J,"ASSINADO")) | D9: =IFERROR(IF(A9="","",C9/SUM($C$6:$C$20)),0) | E9: =IFERROR(IF(A9="","",C9/B9),0)
B10: =IF(A10="","",COUNTIFS('Base de Dados'!C:C,A10,'Base de Dados'!J:J,"ASSINADO")) | C10: =IF(A10="","",SUMIFS('Base de Dados'!I:I,'Base de Dados'!C:C,A10,'Base de Dados'!J:J,"ASSINADO")) | D10: =IFERROR(IF(A10="","",C10/SUM($C$6:$C$20)),0) | E10: =IFERROR(IF(A10="","",C10/B10),0)
B11: =IF(A11="","",COUNTIFS('Base de Dados'!C:C,A11,'Base de Dados'!J:J,"ASSINADO")) | C11: =IF(A11="","",SUMIFS('Base de Dados'!I:I,'Base de Dados'!C:C,A11,'Base de Dados'!J:J,"ASSINADO")) | D11: =IFERROR(IF(A11="","",C11/SUM($C$6:$C$20)),0) | E11: =IFERROR(IF(A11="","",C11/B11),0)
B12: =IF(A12="","",COUNTIFS('Base de Dados'!C:C,A12,'Base de Dados'!J:J,"ASSINADO")) | C12: =IF(A12="","",SUMIFS('Base de Dados'!I:I,'Base de Dados'!C:C,A12,'Base de Dados'!J:J,"ASSINADO")) | D12: =IFERROR(IF(A12="","",C12/SUM($C$6:$C$20)),0) | E12: =IFERROR(IF(A12="","",C12/B12),0)
B13: =IF(A13="","",COUNTIFS('Base de Dados'!C:C,A13,'Base de Dados'!J:J,"ASSINADO")) | C13: =IF(A13="","",SUMIFS('Base de Dados'!I:I,'Base de Dados'!C:C,A13,'Base de Dados'!J:J,"ASSINADO")) | D13: =IFERROR(IF(A13="","",C13/SUM($C$6:$C$20)),0) | E13: =IFERROR(IF(A13="","",C13/B13),0)
B14: =IF(A14="","",COUNTIFS('Base de Dados'!C:C,A14,'Base de Dados'!J:J,"ASSINADO")) | C14: =IF(A14="","",SUMIFS('Base de Dados'!I:I,'Base de Dados'!C:C,A14,'Base de Dados'!J:J,"ASSINADO")) | D14: =IFERROR(IF(A14="","",C14/SUM($C$6:$C$20)),0) | E14: =IFERROR(IF(A14="","",C14/B14),0)
B15: =IF(A15="","",COUNTIFS('Base de Dados'!C:C,A15,'Base de Dados'!J:J,"ASSINADO")) | C15: =IF(A15="","",SUMIFS('Base de Dados'!I:I,'Base de Dados'!C:C,A15,'Base de Dados'!J:J,"ASSINADO")) | D15: =IFERROR(IF(A15="","",C15/SUM($C$6:$C$20)),0) | E15: =IFERROR(IF(A15="","",C15/B15),0)
B16: =IF(A16="","",COUNTIFS('Base de Dados'!C:C,A16,'Base de Dados'!J:J,"ASSINADO")) | C16: =IF(A16="","",SUMIFS('Base de Dados'!I:I,'Base de Dados'!C:C,A16,'Base de Dados'!J:J,"ASSINADO")) | D16: =IFERROR(IF(A16="","",C16/SUM($C$6:$C$20)),0) | E16: =IFERROR(IF(A16="","",C16/B16),0)
B17: =IF(A17="","",COUNTIFS('Base de Dados'!C:C,A17,'Base de Dados'!J:J,"ASSINADO")) | C17: =IF(A17="","",SUMIFS('Base de Dados'!I:I,'Base de Dados'!C:C,A17,'Base de Dados'!J:J,"ASSINADO")) | D17: =IFERROR(IF(A17="","",C17/SUM($C$6:$C$20)),0) | E17: =IFERROR(IF(A17="","",C17/B17),0)
... B20: =IF(A20="","",COUNTIFS('Base de Dados'!C:C,A20,'Base de Dados'!J:J,"ASSINADO")) | C20: =IF(A20="","",SUMIFS('Base de Dados'!I:I,'Base de Dados'!C:C,A20,'Base de Dados'!J:J,"ASSINADO")) | D20: =IFERROR(IF(A20="","",C20/SUM($C$6:$C$20)),0) | E20: =IFERROR(IF(A20="","",C20/B20),0)
A21: TOTAL | B21: =SUM(B6:B20) | C21: =SUM(C6:C20) | D21: =IFERROR(C21/SUMIFS('Base de Dados'!I:I,'Base de Dados'!J:J,"ASSINADO"),0)
A24: DIRETO vs PARCEIROS
A25: CANAL | B25: FATURAMENTO | C25: % PARTICIPAÇÃO
A26: DIRETO (sem parceiro) | B26: =SUMIFS('Base de Dados'!I:I,'Base de Dados'!J:J,"ASSINADO",'Base de Dados'!C:C,"") | C26: =IFERROR(B26/(B26+B27),0)
A27: PARCEIROS | B27: =C21 | C27: =IFERROR(B27/(B26+B27),0)

Sheet Realizado por Hunter
A1: FATURAMENTO REALIZADO (ASSINADO) - POR HUNTER E MÊS
A3: HUNTER | B3: JAN | C3: FEV | D3: MAR | E3: ABR | F3: MAI | G3: JUN | H3: JUL | I3: AGO | J3: SET | K3: OUT | L3: NOV | M3: DEZ | N3: TOTAL
A4: ANDERSON | B4: =SUMIFS('Base de Dados'!I:I,'Base de Dados'!A:A,A4,'Base de Dados'!L:L,"JAN",'Base de Dados'!J:J,"ASSINADO") | C4: =SUMIFS('Base de Dados'!I:I,'Base de Dados'!A:A,A4,'Base de Dados'!L:L,"FEV",'Base de Dados'!J:J,"ASSINADO") | D4: =SUMIFS('Base de Dados'!I:I,'Base de Dados'!A:A,A4,'Base de Dados'!L:L,"MAR",'Base de Dados'!J:J,"ASSINADO") | E4: =SUMIFS('Base de Dados'!I:I,'Base de Dados'!A:A,A4,'Base de Dados'!L:L,"ABR",'Base de Dados'!J:J,"ASSINADO") | F4: =SUMIFS('Base de Dados'!I:I,'Base de Dados'!A:A,A4,'Base de Dados'!L:L,"MAI",'Base de Dados'!J:J,"ASSINADO") | G4: =SUMIFS('Base de Dados'!I:I,'Base de Dados'!A:A,A4,'Base de Dados'!L:L,"JUN",'Base de Dados'!J:J,"ASSINADO") | H4: =SUMIFS('Base de Dados'!I:I,'Base de Dados'!A:A,A4,'Base de Dados'!L:L,"JUL",'Base de Dados'!J:J,"ASSINADO") | I4: =SUMIFS('Base de Dados'!I:I,'Base de Dados'!A:A,A4,'Base de Dados'!L:L,"AGO",'Base de Dados'!J:J,"ASSINADO") | J4: =SUMIFS('Base de Dados'!I:I,'Base de Dados'!A:A,A4,'Base de Dados'!L:L,"SET",'Base de Dados'!J:J,"ASSINADO") | K4: =SUMIFS('Base de Dados'!I:I,'Base de Dados'!A:A,A4,'Base de Dados'!L:L,"OUT",'Base de Dados'!J:J,"ASSINADO") | L4: =SUMIFS('Base de Dados'!I:I,'Base de Dados'!A:A,A4,'Base de Dados'!L:L,"NOV",'Base de Dados'!J:J,"ASSINADO") | M4: =SUMIFS('Base de Dados'!I:I,'Base de Dados'!A:A,A4,'Base de Dados'!L:L,"DEZ",'Base de Dados'!J:J,"ASSINADO") | N4: =SUM(B4:M4)
A5: ARTHUR | B5: =SUMIFS('Base de Dados'!I:I,'Base de Dados'!A:A,A5,'Base de Dados'!L:L,"JAN",'Base de Dados'!J:J,"ASSINADO") | C5: =SUMIFS('Base de Dados'!I:I,'Base de Dados'!A:A,A5,'Base de Dados'!L:L,"FEV",'Base de Dados'!J:J,"ASSINADO") | D5: =SUMIFS('Base de Dados'!I:I,'Base de Dados'!A:A,A5,'Base de Dados'!L:L,"MAR",'Base de Dados'!J:J,"ASSINADO") | E5: =SUMIFS('Base de Dados'!I:I,'Base de Dados'!A:A,A5,'Base de Dados'!L:L,"ABR",'Base de Dados'!J:J,"ASSINADO") | F5: =SUMIFS('Base de Dados'!I:I,'Base de Dados'!A:A,A5,'Base de Dados'!L:L,"MAI",'Base de Dados'!J:J,"ASSINADO") | G5: =SUMIFS('Base de Dados'!I:I,'Base de Dados'!A:A,A5,'Base de Dados'!L:L,"JUN",'Base de Dados'!J:J,"ASSINADO") | H5: =SUMIFS('Base de Dados'!I:I,'Base de Dados'!A:A,A5,'Base de Dados'!L:L,"JUL",'Base de Dados'!J:J,"ASSINADO") | I5: =SUMIFS('Base de Dados'!I:I,'Base de Dados'!A:A,A5,'Base de Dados'!L:L,"AGO",'Base de Dados'!J:J,"ASSINADO") | J5: =SUMIFS('Base de Dados'!I:I,'Base de Dados'!A:A,A5,'Base de Dados'!L:L,"SET",'Base de Dados'!J:J,"ASSINADO") | K5: =SUMIFS('Base de Dados'!I:I,'Base de Dados'!A:A,A5,'Base de Dados'!L:L,"OUT",'Base de Dados'!J:J,"ASSINADO") | L5: =SUMIFS('Base de Dados'!I:I,'Base de Dados'!A:A,A5,'Base de Dados'!L:L,"NOV",'Base de Dados'!J:J,"ASSINADO") | M5: =SUMIFS('Base de Dados'!I:I,'Base de Dados'!A:A,A5,'Base de Dados'!L:L,"DEZ",'Base de Dados'!J:J,"ASSINADO") | N5: =SUM(B5:M5)
A6: BRUNA | B6: =SUMIFS('Base de Dados'!I:I,'Base de Dados'!A:A,A6,'Base de Dados'!L:L,"JAN",'Base de Dados'!J:J,"ASSINADO") | C6: =SUMIFS('Base de Dados'!I:I,'Base de Dados'!A:A,A6,'Base de Dados'!L:L,"FEV",'Base de Dados'!J:J,"ASSINADO") | D6: =SUMIFS('Base de Dados'!I:I,'Base de Dados'!A:A,A6,'Base de Dados'!L:L,"MAR",'Base de Dados'!J:J,"ASSINADO") | E6: =SUMIFS('Base de Dados'!I:I,'Base de Dados'!A:A,A6,'Base de Dados'!L:L,"ABR",'Base de Dados'!J:J,"ASSINADO") | F6: =SUMIFS('Base de Dados'!I:I,'Base de Dados'!A:A,A6,'Base de Dados'!L:L,"MAI",'Base de Dados'!J:J,"ASSINADO") | G6: =SUMIFS('Base de Dados'!I:I,'Base de Dados'!A:A,A6,'Base de Dados'!L:L,"JUN",'Base de Dados'!J:J,"ASSINADO") | H6: =SUMIFS('Base de Dados'!I:I,'Base de Dados'!A:A,A6,'Base de Dados'!L:L,"JUL",'Base de Dados'!J:J,"ASSINADO") | I6: =SUMIFS('Base de Dados'!I:I,'Base de Dados'!A:A,A6,'Base de Dados'!L:L,"AGO",'Base de Dados'!J:J,"ASSINADO") | J6: =SUMIFS('Base de Dados'!I:I,'Base de Dados'!A:A,A6,'Base de Dados'!L:L,"SET",'Base de Dados'!J:J,"ASSINADO") | K6: =SUMIFS('Base de Dados'!I:I,'Base de Dados'!A:A,A6,'Base de Dados'!L:L,"OUT",'Base de Dados'!J:J,"ASSINADO") | L6: =SUMIFS('Base de Dados'!I:I,'Base de Dados'!A:A,A6,'Base de Dados'!L:L,"NOV",'Base de Dados'!J:J,"ASSINADO") | M6: =SUMIFS('Base de Dados'!I:I,'Base de Dados'!A:A,A6,'Base de Dados'!L:L,"DEZ",'Base de Dados'!J:J,"ASSINADO") | N6: =SUM(B6:M6)
A7: CINTHIA | B7: =SUMIFS('Base de Dados'!I:I,'Base de Dados'!A:A,A7,'Base de Dados'!L:L,"JAN",'Base de Dados'!J:J,"ASSINADO") | C7: =SUMIFS('Base de Dados'!I:I,'Base de Dados'!A:A,A7,'Base de Dados'!L:L,"FEV",'Base de Dados'!J:J,"ASSINADO") | D7: =SUMIFS('Base de Dados'!I:I,'Base de Dados'!A:A,A7,'Base de Dados'!L:L,"MAR",'Base de Dados'!J:J,"ASSINADO") | E7: =SUMIFS('Base de Dados'!I:I,'Base de Dados'!A:A,A7,'Base de Dados'!L:L,"ABR",'Base de Dados'!J:J,"ASSINADO") | F7: =SUMIFS('Base de Dados'!I:I,'Base de Dados'!A:A,A7,'Base de Dados'!L:L,"MAI",'Base de Dados'!J:J,"ASSINADO") | G7: =SUMIFS('Base de Dados'!I:I,'Base de Dados'!A:A,A7,'Base de Dados'!L:L,"JUN",'Base de Dados'!J:J,"ASSINADO") | H7: =SUMIFS('Base de Dados'!I:I,'Base de Dados'!A:A,A7,'Base de Dados'!L:L,"JUL",'Base de Dados'!J:J,"ASSINADO") | I7: =SUMIFS('Base de Dados'!I:I,'Base de Dados'!A:A,A7,'Base de Dados'!L:L,"AGO",'Base de Dados'!J:J,"ASSINADO") | J7: =SUMIFS('Base de Dados'!I:I,'Base de Dados'!A:A,A7,'Base de Dados'!L:L,"SET",'Base de Dados'!J:J,"ASSINADO") | K7: =SUMIFS('Base de Dados'!I:I,'Base de Dados'!A:A,A7,'Base de Dados'!L:L,"OUT",'Base de Dados'!J:J,"ASSINADO") | L7: =SUMIFS('Base de Dados'!I:I,'Base de Dados'!A:A,A7,'Base de Dados'!L:L,"NOV",'Base de Dados'!J:J,"ASSINADO") | M7: =SUMIFS('Base de Dados'!I:I,'Base de Dados'!A:A,A7,'Base de Dados'!L:L,"DEZ",'Base de Dados'!J:J,"ASSINADO") | N7: =SUM(B7:M7)
A8: DIMAS | B8: =SUMIFS('Base de Dados'!I:I,'Base de Dados'!A:A,A8,'Base de Dados'!L:L,"JAN",'Base de Dados'!J:J,"ASSINADO") | C8: =SUMIFS('Base de Dados'!I:I,'Base de Dados'!A:A,A8,'Base de Dados'!L:L,"FEV",'Base de Dados'!J:J,"ASSINADO") | D8: =SUMIFS('Base de Dados'!I:I,'Base de Dados'!A:A,A8,'Base de Dados'!L:L,"MAR",'Base de Dados'!J:J,"ASSINADO") | E8: =SUMIFS('Base de Dados'!I:I,'Base de Dados'!A:A,A8,'Base de Dados'!L:L,"ABR",'Base de Dados'!J:J,"ASSINADO") | F8: =SUMIFS('Base de Dados'!I:I,'Base de Dados'!A:A,A8,'Base de Dados'!L:L,"MAI",'Base de Dados'!J:J,"ASSINADO") | G8: =SUMIFS('Base de Dados'!I:I,'Base de Dados'!A:A,A8,'Base de Dados'!L:L,"JUN",'Base de Dados'!J:J,"ASSINADO") | H8: =SUMIFS('Base de Dados'!I:I,'Base de Dados'!A:A,A8,'Base de Dados'!L:L,"JUL",'Base de Dados'!J:J,"ASSINADO") | I8: =SUMIFS('Base de Dados'!I:I,'Base de Dados'!A:A,A8,'Base de Dados'!L:L,"AGO",'Base de Dados'!J:J,"ASSINADO") | J8: =SUMIFS('Base de Dados'!I:I,'Base de Dados'!A:A,A8,'Base de Dados'!L:L,"SET",'Base de Dados'!J:J,"ASSINADO") | K8: =SUMIFS('Base de Dados'!I:I,'Base de Dados'!A:A,A8,'Base de Dados'!L:L,"OUT",'Base de Dados'!J:J,"ASSINADO") | L8: =SUMIFS('Base de Dados'!I:I,'Base de Dados'!A:A,A8,'Base de Dados'!L:L,"NOV",'Base de Dados'!J:J,"ASSINADO") | M8: =SUMIFS('Base de Dados'!I:I,'Base de Dados'!A:A,A8,'Base de Dados'!L:L,"DEZ",'Base de Dados'!J:J,"ASSINADO") | N8: =SUM(B8:M8)
A9: FORTALEZA 2 | B9: =SUMIFS('Base de Dados'!I:I,'Base de Dados'!A:A,A9,'Base de Dados'!L:L,"JAN",'Base de Dados'!J:J,"ASSINADO") | C9: =SUMIFS('Base de Dados'!I:I,'Base de Dados'!A:A,A9,'Base de Dados'!L:L,"FEV",'Base de Dados'!J:J,"ASSINADO") | D9: =SUMIFS('Base de Dados'!I:I,'Base de Dados'!A:A,A9,'Base de Dados'!L:L,"MAR",'Base de Dados'!J:J,"ASSINADO") | E9: =SUMIFS('Base de Dados'!I:I,'Base de Dados'!A:A,A9,'Base de Dados'!L:L,"ABR",'Base de Dados'!J:J,"ASSINADO") | F9: =SUMIFS('Base de Dados'!I:I,'Base de Dados'!A:A,A9,'Base de Dados'!L:L,"MAI",'Base de Dados'!J:J,"ASSINADO") | G9: =SUMIFS('Base de Dados'!I:I,'Base de Dados'!A:A,A9,'Base de Dados'!L:L,"JUN",'Base de Dados'!J:J,"ASSINADO") | H9: =SUMIFS('Base de Dados'!I:I,'Base de Dados'!A:A,A9,'Base de Dados'!L:L,"JUL",'Base de Dados'!J:J,"ASSINADO") | I9: =SUMIFS('Base de Dados'!I:I,'Base de Dados'!A:A,A9,'Base de Dados'!L:L,"AGO",'Base de Dados'!J:J,"ASSINADO") | J9: =SUMIFS('Base de Dados'!I:I,'Base de Dados'!A:A,A9,'Base de Dados'!L:L,"SET",'Base de Dados'!J:J,"ASSINADO") | K9: =SUMIFS('Base de Dados'!I:I,'Base de Dados'!A:A,A9,'Base de Dados'!L:L,"OUT",'Base de Dados'!J:J,"ASSINADO") | L9: =SUMIFS('Base de Dados'!I:I,'Base de Dados'!A:A,A9,'Base de Dados'!L:L,"NOV",'Base de Dados'!J:J,"ASSINADO") | M9: =SUMIFS('Base de Dados'!I:I,'Base de Dados'!A:A,A9,'Base de Dados'!L:L,"DEZ",'Base de Dados'!J:J,"ASSINADO") | N9: =SUM(B9:M9)
A10: HEITOR | B10: =SUMIFS('Base de Dados'!I:I,'Base de Dados'!A:A,A10,'Base de Dados'!L:L,"JAN",'Base de Dados'!J:J,"ASSINADO") | C10: =SUMIFS('Base de Dados'!I:I,'Base de Dados'!A:A,A10,'Base de Dados'!L:L,"FEV",'Base de Dados'!J:J,"ASSINADO") | D10: =SUMIFS('Base de Dados'!I:I,'Base de Dados'!A:A,A10,'Base de Dados'!L:L,"MAR",'Base de Dados'!J:J,"ASSINADO") | E10: =SUMIFS('Base de Dados'!I:I,'Base de Dados'!A:A,A10,'Base de Dados'!L:L,"ABR",'Base de Dados'!J:J,"ASSINADO") | F10: =SUMIFS('Base de Dados'!I:I,'Base de Dados'!A:A,A10,'Base de Dados'!L:L,"MAI",'Base de Dados'!J:J,"ASSINADO") | G10: =SUMIFS('Base de Dados'!I:I,'Base de Dados'!A:A,A10,'Base de Dados'!L:L,"JUN",'Base de Dados'!J:J,"ASSINADO") | H10: =SUMIFS('Base de Dados'!I:I,'Base de Dados'!A:A,A10,'Base de Dados'!L:L,"JUL",'Base de Dados'!J:J,"ASSINADO") | I10: =SUMIFS('Base de Dados'!I:I,'Base de Dados'!A:A,A10,'Base de Dados'!L:L,"AGO",'Base de Dados'!J:J,"ASSINADO") | J10: =SUMIFS('Base de Dados'!I:I,'Base de Dados'!A:A,A10,'Base de Dados'!L:L,"SET",'Base de Dados'!J:J,"ASSINADO") | K10: =SUMIFS('Base de Dados'!I:I,'Base de Dados'!A:A,A10,'Base de Dados'!L:L,"OUT",'Base de Dados'!J:J,"ASSINADO") | L10: =SUMIFS('Base de Dados'!I:I,'Base de Dados'!A:A,A10,'Base de Dados'!L:L,"NOV",'Base de Dados'!J:J,"ASSINADO") | M10: =SUMIFS('Base de Dados'!I:I,'Base de Dados'!A:A,A10,'Base de Dados'!L:L,"DEZ",'Base de Dados'!J:J,"ASSINADO") | N10: =SUM(B10:M10)
A11: HUDSON | B11: =SUMIFS('Base de Dados'!I:I,'Base de Dados'!A:A,A11,'Base de Dados'!L:L,"JAN",'Base de Dados'!J:J,"ASSINADO") | C11: =SUMIFS('Base de Dados'!I:I,'Base de Dados'!A:A,A11,'Base de Dados'!L:L,"FEV",'Base de Dados'!J:J,"ASSINADO") | D11: =SUMIFS('Base de Dados'!I:I,'Base de Dados'!A:A,A11,'Base de Dados'!L:L,"MAR",'Base de Dados'!J:J,"ASSINADO") | E11: =SUMIFS('Base de Dados'!I:I,'Base de Dados'!A:A,A11,'Base de Dados'!L:L,"ABR",'Base de Dados'!J:J,"ASSINADO") | F11: =SUMIFS('Base de Dados'!I:I,'Base de Dados'!A:A,A11,'Base de Dados'!L:L,"MAI",'Base de Dados'!J:J,"ASSINADO") | G11: =SUMIFS('Base de Dados'!I:I,'Base de Dados'!A:A,A11,'Base de Dados'!L:L,"JUN",'Base de Dados'!J:J,"ASSINADO") | H11: =SUMIFS('Base de Dados'!I:I,'Base de Dados'!A:A,A11,'Base de Dados'!L:L,"JUL",'Base de Dados'!J:J,"ASSINADO") | I11: =SUMIFS('Base de Dados'!I:I,'Base de Dados'!A:A,A11,'Base de Dados'!L:L,"AGO",'Base de Dados'!J:J,"ASSINADO") | J11: =SUMIFS('Base de Dados'!I:I,'Base de Dados'!A:A,A11,'Base de Dados'!L:L,"SET",'Base de Dados'!J:J,"ASSINADO") | K11: =SUMIFS('Base de Dados'!I:I,'Base de Dados'!A:A,A11,'Base de Dados'!L:L,"OUT",'Base de Dados'!J:J,"ASSINADO") | L11: =SUMIFS('Base de Dados'!I:I,'Base de Dados'!A:A,A11,'Base de Dados'!L:L,"NOV",'Base de Dados'!J:J,"ASSINADO") | M11: =SUMIFS('Base de Dados'!I:I,'Base de Dados'!A:A,A11,'Base de Dados'!L:L,"DEZ",'Base de Dados'!J:J,"ASSINADO") | N11: =SUM(B11:M11)
A12: KATARINI | B12: =SUMIFS('Base de Dados'!I:I,'Base de Dados'!A:A,A12,'Base de Dados'!L:L,"JAN",'Base de Dados'!J:J,"ASSINADO") | C12: =SUMIFS('Base de Dados'!I:I,'Base de Dados'!A:A,A12,'Base de Dados'!L:L,"FEV",'Base de Dados'!J:J,"ASSINADO") | D12: =SUMIFS('Base de Dados'!I:I,'Base de Dados'!A:A,A12,'Base de Dados'!L:L,"MAR",'Base de Dados'!J:J,"ASSINADO") | E12: =SUMIFS('Base de Dados'!I:I,'Base de Dados'!A:A,A12,'Base de Dados'!L:L,"ABR",'Base de Dados'!J:J,"ASSINADO") | F12: =SUMIFS('Base de Dados'!I:I,'Base de Dados'!A:A,A12,'Base de Dados'!L:L,"MAI",'Base de Dados'!J:J,"ASSINADO") | G12: =SUMIFS('Base de Dados'!I:I,'Base de Dados'!A:A,A12,'Base de Dados'!L:L,"JUN",'Base de Dados'!J:J,"ASSINADO") | H12: =SUMIFS('Base de Dados'!I:I,'Base de Dados'!A:A,A12,'Base de Dados'!L:L,"JUL",'Base de Dados'!J:J,"ASSINADO") | I12: =SUMIFS('Base de Dados'!I:I,'Base de Dados'!A:A,A12,'Base de Dados'!L:L,"AGO",'Base de Dados'!J:J,"ASSINADO") | J12: =SUMIFS('Base de Dados'!I:I,'Base de Dados'!A:A,A12,'Base de Dados'!L:L,"SET",'Base de Dados'!J:J,"ASSINADO") | K12: =SUMIFS('Base de Dados'!I:I,'Base de Dados'!A:A,A12,'Base de Dados'!L:L,"OUT",'Base de Dados'!J:J,"ASSINADO") | L12: =SUMIFS('Base de Dados'!I:I,'Base de Dados'!A:A,A12,'Base de Dados'!L:L,"NOV",'Base de Dados'!J:J,"ASSINADO") | M12: =SUMIFS('Base de Dados'!I:I,'Base de Dados'!A:A,A12,'Base de Dados'!L:L,"DEZ",'Base de Dados'!J:J,"ASSINADO") | N12: =SUM(B12:M12)
A13: LEANDRO | B13: =SUMIFS('Base de Dados'!I:I,'Base de Dados'!A:A,A13,'Base de Dados'!L:L,"JAN",'Base de Dados'!J:J,"ASSINADO") | C13: =SUMIFS('Base de Dados'!I:I,'Base de Dados'!A:A,A13,'Base de Dados'!L:L,"FEV",'Base de Dados'!J:J,"ASSINADO") | D13: =SUMIFS('Base de Dados'!I:I,'Base de Dados'!A:A,A13,'Base de Dados'!L:L,"MAR",'Base de Dados'!J:J,"ASSINADO") | E13: =SUMIFS('Base de Dados'!I:I,'Base de Dados'!A:A,A13,'Base de Dados'!L:L,"ABR",'Base de Dados'!J:J,"ASSINADO") | F13: =SUMIFS('Base de Dados'!I:I,'Base de Dados'!A:A,A13,'Base de Dados'!L:L,"MAI",'Base de Dados'!J:J,"ASSINADO") | G13: =SUMIFS('Base de Dados'!I:I,'Base de Dados'!A:A,A13,'Base de Dados'!L:L,"JUN",'Base de Dados'!J:J,"ASSINADO") | H13: =SUMIFS('Base de Dados'!I:I,'Base de Dados'!A:A,A13,'Base de Dados'!L:L,"JUL",'Base de Dados'!J:J,"ASSINADO") | I13: =SUMIFS('Base de Dados'!I:I,'Base de Dados'!A:A,A13,'Base de Dados'!L:L,"AGO",'Base de Dados'!J:J,"ASSINADO") | J13: =SUMIFS('Base de Dados'!I:I,'Base de Dados'!A:A,A13,'Base de Dados'!L:L,"SET",'Base de Dados'!J:J,"ASSINADO") | K13: =SUMIFS('Base de Dados'!I:I,'Base de Dados'!A:A,A13,'Base de Dados'!L:L,"OUT",'Base de Dados'!J:J,"ASSINADO") | L13: =SUMIFS('Base de Dados'!I:I,'Base de Dados'!A:A,A13,'Base de Dados'!L:L,"NOV",'Base de Dados'!J:J,"ASSINADO") | M13: =SUMIFS('Base de Dados'!I:I,'Base de Dados'!A:A,A13,'Base de Dados'!L:L,"DEZ",'Base de Dados'!J:J,"ASSINADO") | N13: =SUM(B13:M13)
A14: NATHALIA | B14: =SUMIFS('Base de Dados'!I:I,'Base de Dados'!A:A,A14,'Base de Dados'!L:L,"JAN",'Base de Dados'!J:J,"ASSINADO") | C14: =SUMIFS('Base de Dados'!I:I,'Base de Dados'!A:A,A14,'Base de Dados'!L:L,"FEV",'Base de Dados'!J:J,"ASSINADO") | D14: =SUMIFS('Base de Dados'!I:I,'Base de Dados'!A:A,A14,'Base de Dados'!L:L,"MAR",'Base de Dados'!J:J,"ASSINADO") | E14: =SUMIFS('Base de Dados'!I:I,'Base de Dados'!A:A,A14,'Base de Dados'!L:L,"ABR",'Base de Dados'!J:J,"ASSINADO") | F14: =SUMIFS('Base de Dados'!I:I,'Base de Dados'!A:A,A14,'Base de Dados'!L:L,"MAI",'Base de Dados'!J:J,"ASSINADO") | G14: =SUMIFS('Base de Dados'!I:I,'Base de Dados'!A:A,A14,'Base de Dados'!L:L,"JUN",'Base de Dados'!J:J,"ASSINADO") | H14: =SUMIFS('Base de Dados'!I:I,'Base de Dados'!A:A,A14,'Base de Dados'!L:L,"JUL",'Base de Dados'!J:J,"ASSINADO") | I14: =SUMIFS('Base de Dados'!I:I,'Base de Dados'!A:A,A14,'Base de Dados'!L:L,"AGO",'Base de Dados'!J:J,"ASSINADO") | J14: =SUMIFS('Base de Dados'!I:I,'Base de Dados'!A:A,A14,'Base de Dados'!L:L,"SET",'Base de Dados'!J:J,"ASSINADO") | K14: =SUMIFS('Base de Dados'!I:I,'Base de Dados'!A:A,A14,'Base de Dados'!L:L,"OUT",'Base de Dados'!J:J,"ASSINADO") | L14: =SUMIFS('Base de Dados'!I:I,'Base de Dados'!A:A,A14,'Base de Dados'!L:L,"NOV",'Base de Dados'!J:J,"ASSINADO") | M14: =SUMIFS('Base de Dados'!I:I,'Base de Dados'!A:A,A14,'Base de Dados'!L:L,"DEZ",'Base de Dados'!J:J,"ASSINADO") | N14: =SUM(B14:M14)
A15: ORLANDO | B15: =SUMIFS('Base de Dados'!I:I,'Base de Dados'!A:A,A15,'Base de Dados'!L:L,"JAN",'Base de Dados'!J:J,"ASSINADO") | C15: =SUMIFS('Base de Dados'!I:I,'Base de Dados'!A:A,A15,'Base de Dados'!L:L,"FEV",'Base de Dados'!J:J,"ASSINADO") | D15: =SUMIFS('Base de Dados'!I:I,'Base de Dados'!A:A,A15,'Base de Dados'!L:L,"MAR",'Base de Dados'!J:J,"ASSINADO") | E15: =SUMIFS('Base de Dados'!I:I,'Base de Dados'!A:A,A15,'Base de Dados'!L:L,"ABR",'Base de Dados'!J:J,"ASSINADO") | F15: =SUMIFS('Base de Dados'!I:I,'Base de Dados'!A:A,A15,'Base de Dados'!L:L,"MAI",'Base de Dados'!J:J,"ASSINADO") | G15: =SUMIFS('Base de Dados'!I:I,'Base de Dados'!A:A,A15,'Base de Dados'!L:L,"JUN",'Base de Dados'!J:J,"ASSINADO") | H15: =SUMIFS('Base de Dados'!I:I,'Base de Dados'!A:A,A15,'Base de Dados'!L:L,"JUL",'Base de Dados'!J:J,"ASSINADO") | I15: =SUMIFS('Base de Dados'!I:I,'Base de Dados'!A:A,A15,'Base de Dados'!L:L,"AGO",'Base de Dados'!J:J,"ASSINADO") | J15: =SUMIFS('Base de Dados'!I:I,'Base de Dados'!A:A,A15,'Base de Dados'!L:L,"SET",'Base de Dados'!J:J,"ASSINADO") | K15: =SUMIFS('Base de Dados'!I:I,'Base de Dados'!A:A,A15,'Base de Dados'!L:L,"OUT",'Base de Dados'!J:J,"ASSINADO") | L15: =SUMIFS('Base de Dados'!I:I,'Base de Dados'!A:A,A15,'Base de Dados'!L:L,"NOV",'Base de Dados'!J:J,"ASSINADO") | M15: =SUMIFS('Base de Dados'!I:I,'Base de Dados'!A:A,A15,'Base de Dados'!L:L,"DEZ",'Base de Dados'!J:J,"ASSINADO") | N15: =SUM(B15:M15)
... A19: THIAGO | B19: =SUMIFS('Base de Dados'!I:I,'Base de Dados'!A:A,A19,'Base de Dados'!L:L,"JAN",'Base de Dados'!J:J,"ASSINADO") | C19: =SUMIFS('Base de Dados'!I:I,'Base de Dados'!A:A,A19,'Base de Dados'!L:L,"FEV",'Base de Dados'!J:J,"ASSINADO") | D19: =SUMIFS('Base de Dados'!I:I,'Base de Dados'!A:A,A19,'Base de Dados'!L:L,"MAR",'Base de Dados'!J:J,"ASSINADO") | E19: =SUMIFS('Base de Dados'!I:I,'Base de Dados'!A:A,A19,'Base de Dados'!L:L,"ABR",'Base de Dados'!J:J,"ASSINADO") | F19: =SUMIFS('Base de Dados'!I:I,'Base de Dados'!A:A,A19,'Base de Dados'!L:L,"MAI",'Base de Dados'!J:J,"ASSINADO") | G19: =SUMIFS('Base de Dados'!I:I,'Base de Dados'!A:A,A19,'Base de Dados'!L:L,"JUN",'Base de Dados'!J:J,"ASSINADO") | H19: =SUMIFS('Base de Dados'!I:I,'Base de Dados'!A:A,A19,'Base de Dados'!L:L,"JUL",'Base de Dados'!J:J,"ASSINADO") | I19: =SUMIFS('Base de Dados'!I:I,'Base de Dados'!A:A,A19,'Base de Dados'!L:L,"AGO",'Base de Dados'!J:J,"ASSINADO") | J19: =SUMIFS('Base de Dados'!I:I,'Base de Dados'!A:A,A19,'Base de Dados'!L:L,"SET",'Base de Dados'!J:J,"ASSINADO") | K19: =SUMIFS('Base de Dados'!I:I,'Base de Dados'!A:A,A19,'Base de Dados'!L:L,"OUT",'Base de Dados'!J:J,"ASSINADO") | L19: =SUMIFS('Base de Dados'!I:I,'Base de Dados'!A:A,A19,'Base de Dados'!L:L,"NOV",'Base de Dados'!J:J,"ASSINADO") | M19: =SUMIFS('Base de Dados'!I:I,'Base de Dados'!A:A,A19,'Base de Dados'!L:L,"DEZ",'Base de Dados'!J:J,"ASSINADO") | N19: =SUM(B19:M19)
A20: TOTAL | B20: =SUM(B4:B19) | C20: =SUM(C4:C19) | D20: =SUM(D4:D19) | E20: =SUM(E4:E19) | F20: =SUM(F4:F19) | G20: =SUM(G4:G19) | H20: =SUM(H4:H19) | I20: =SUM(I4:I19) | ... M20: =SUM(M4:M19) | N20: =SUM(B20:M20)

Sheet Metas
A1: METAS POR HUNTER (R$)
A3: HUNTER | B3: JAN | C3: FEV | D3: MAR | E3: ABR | F3: MAI | G3: JUN | H3: JUL | I3: AGO | J3: SET | K3: OUT | L3: NOV | M3: DEZ | N3: TOTAL ANO
A4: HUDSON | B4: 168000 | C4: 252000 | D4: 336000 | E4: 336000 | F4: 252000 | G4: 336000 | H4: 504000 | I4: 378000 | J4: 504000 | K4: 504000 | L4: 378000 | M4: 252000 | N4: =SUM(B4:M4)
A5: DIMAS | B5: 128000 | C5: 192000 | D5: 256000 | E5: 256000 | F5: 192000 | G5: 256000 | H5: 384000 | I5: 288000 | J5: 384000 | K5: 384000 | L5: 288000 | M5: 192000 | N5: =SUM(B5:M5)
A6: HEITOR | B6: 128000 | C6: 192000 | D6: 256000 | E6: 256000 | F6: 192000 | G6: 256000 | H6: 384000 | I6: 288000 | J6: 384000 | K6: 384000 | L6: 288000 | M6: 192000 | N6: =SUM(B6:M6)
A7: CINTHIA | B7: 128000 | C7: 192000 | D7: 256000 | E7: 256000 | F7: 192000 | G7: 256000 | H7: 384000 | I7: 288000 | J7: 384000 | K7: 384000 | L7: 288000 | M7: 192000 | N7: =SUM(B7:M7)
A8: BRUNA | B8: 128000 | C8: 192000 | D8: 256000 | E8: 256000 | F8: 192000 | G8: 256000 | H8: 384000 | I8: 288000 | J8: 384000 | K8: 384000 | L8: 288000 | M8: 192000 | N8: =SUM(B8:M8)
A9: LEANDRO | B9: 128000 | C9: 192000 | D9: 256000 | E9: 256000 | F9: 192000 | G9: 256000 | H9: 384000 | I9: 288000 | J9: 384000 | K9: 384000 | L9: 288000 | M9: 192000 | N9: =SUM(B9:M9)
A10: NATHALIA | B10: 128000 | C10: 192000 | D10: 256000 | E10: 256000 | F10: 192000 | G10: 256000 | H10: 384000 | I10: 288000 | J10: 384000 | K10: 384000 | L10: 288000 | M10: 192000 | N10: =SUM(B10:M10)
A11: ORLANDO | B11: 168000 | C11: 252000 | D11: 336000 | E11: 336000 | F11: 252000 | G11: 336000 | H11: 504000 | I11: 378000 | J11: 504000 | K11: 504000 | L11: 378000 | M11: 252000 | N11: =SUM(B11:M11)
A12: RAUL | B12: 0 | C12: 0 | D12: 264000 | E12: 198000 | F12: 264000 | G12: 264000 | H12: 198000 | I12: 132000 | J12: 264000 | K12: 198000 | L12: 264000 | M12: 128000 | N12: =SUM(B12:M12)
A13: ANDERSON | B13: 0 | C13: 0 | D13: 0 | E13: 100000 | F13: 100000 | G13: 100000 | H13: 300000 | I13: 225000 | J13: 300000 | K13: 300000 | L13: 225000 | M13: 150000 | N13: =SUM(B13:M13)
A14: FORTALEZA 2 | B14: 0 | C14: 0 | D14: 0 | E14: 0 | F14: 0 | G14: 0 | H14: 300000 | I14: 225000 | J14: 300000 | K14: 300000 | L14: 225000 | M14: 150000 | N14: =SUM(B14:M14)
A15: KATARINI | B15: 0 | C15: 0 | D15: 0 | E15: 100000 | F15: 100000 | G15: 100000 | H15: 264000 | I15: 198000 | J15: 264000 | K15: 264000 | L15: 198000 | M15: 132000 | N15: =SUM(B15:M15)
... A18: SILAS | B18: 0 | C18: 0 | D18: 0 | E18: 100000 | F18: 100000 | G18: 100000 | H18: 264000 | I18: 198000 | J18: 264000 | K18: 264000 | L18: 198000 | M18: 132000 | N18: =SUM(B18:M18)
A19: TOTAL | B19: =SUM(B4:B18) | C19: =SUM(C4:C18) | D19: =SUM(D4:D18) | E19: =SUM(E4:E18) | F19: =SUM(F4:F18) | G19: =SUM(G4:G18) | H19: =SUM(H4:H18) | I19: =SUM(I4:I18) | ... M19: =SUM(M4:M18) | N19: =SUM(B19:M19)

Sheet Base de Dados
A1: HUNTER | B1: PRAÇA | C1: PARCEIRO | D1: EMPRESA | E1: PRODUTO | F1: CONTRATO | G1: CRÉDITO | H1: HONORÁRIOS | I1: FATURAMENTO | J1: STATUS | K1: MÊS | L1: MÊS ASSINADO | M1: TEMPERATURA | N1: ORIGEM
A2: BRUNA | B2: São Paulo e Santos | D2: SUPER DOCES MARINGA | E2: EXCL ICMS ST | F2: NOVO | G2: 4214417 | H2: 0.2 | I2: 842883.4 | J2: ASSINADO | K2: DEZ | L2: JAN | M2: QUENTE
A3: BRUNA | B3: São Paulo e Santos | D3: SUPER DOCES MARINGA | E3: PIS/COFINS INSUMOS | F3: NOVO | G3: 77600 | H3: 0.2 | I3: 15520 | J3: ASSINADO | K3: DEZ | L3: JAN | M3: QUENTE
A4: BRUNA | B4: São Paulo e Santos | D4: SUPER DOCES MARINGA | E4: JCP | F4: NOVO | G4: 360065 | H4: 0.2 | I4: 72013 | J4: ASSINADO | K4: DEZ | L4: JAN | M4: QUENTE
A5: BRUNA | B5: São Paulo e Santos | D5: SUPER DOCES MARINGA | E5: SUBVENÇÃO | F5: NOVO | G5: 325440 | H5: 0.2 | I5: 65088 | J5: ASSINADO | K5: DEZ | L5: JAN | M5: QUENTE
A6: BRUNA | B6: São Paulo e Santos | D6: SUPERMERCADOS M FARIA E R GRAVINA LTDA | E6: EXCL ICMS ST BASE COFINS | F6: NOVO | G6: 32136.96 | H6: 0.18 | I6: 23008.6 | J6: ASSINADO | K6: DEZ | L6: JAN | M6: QUENTE
A7: BRUNA | B7: São Paulo e Santos | D7: SUPERMERCADOS M FARIA E R GRAVINA LTDA | E7: PREVIDENCIARIO | F7: NOVO | G7: 256000 | H7: 0.18 | I7: 46080 | J7: ASSINADO | K7: DEZ | L7: JAN | M7: QUENTE
A8: BRUNA | B8: São Paulo e Santos | D8: SUPERMERCADO REPRESA | E8: IRPJ CSLL | F8: NOVO | G8: 71286 | H8: 0.25 | I8: 17821.5 | J8: ASSINADO | K8: DEZ | L8: MAR | M8: QUENTE
A9: BRUNA | B9: São Paulo e Santos | D9: SUPERMERCADO REPRESA | E9: PIS E COFINS | F9: NOVO | G9: 128163 | H9: 0.25 | I9: 32040.75 | J9: ASSINADO | K9: DEZ | L9: MAR | M9: QUENTE
A10: BRUNA | B10: São Paulo e Santos | D10: SUPERMERCADO REPRESA | E10: EXCLUSAO ICMS ST da base PIS E COFINS | F10: NOVO | G10: 282840 | H10: 0.25 | I10: 70710 | J10: ASSINADO | K10: DEZ | L10: MAR | M10: QUENTE
A11: BRUNA | B11: São Paulo e Santos | D11: SUPERMERCADO BATISTINI LTDA | E11: IRPJ E CSLL | F11: NOVO | G11: 142002 | H11: 0.25 | I11: 35500.5 | J11: ASSINADO | K11: DEZ | L11: MAR | M11: QUENTE
A12: BRUNA | B12: São Paulo e Santos | D12: SUPERMERCADO BATISTINI LTDA | F12: NOVO | G12: 1545.63 | H12: 0.25 | I12: 386.41 | J12: ASSINADO | K12: DEZ | L12: MAR | M12: QUENTE
A13: BRUNA | B13: São Paulo e Santos | D13: SUPERMERCADO JARDIM ORQUIDEA LTDA | E13: IRPJ E CSLL | F13: NOVO | G13: 67977 | H13: 0.25 | I13: 16994.25 | J13: ASSINADO | K13: DEZ | L13: MAR | M13: QUENTE
A14: BRUNA | B14: São Paulo e Santos | D14: SUPERMERCADO JARDIM ORQUIDEA LTDA | E14: PIS E COFINS | F14: NOVO | G14: 258965 | H14: 0.25 | I14: 64741.25 | J14: ASSINADO | K14: DEZ | L14: MAR | M14: QUENTE
A15: BRUNA | B15: São Paulo e Santos | D15: SUPERMERCADO BANDEIRA LTDA | E15: PIS E COFINS | F15: NOVO | G15: 268726 | H15: 0.25 | I15: 67181.5 | J15: ASSINADO | K15: JAN | L15: ABR | M15: MORNO
A16: BRUNA | B16: São Paulo e Santos | D16: SUPERMERCADO BANDEIRA LTDA | E16: SUBVENÇAO IRPJ CSLL | F16: NOVO | G16: 1453215 | H16: 0.25 | I16: 363303.75 | J16: ASSINADO | K16: JAN | L16: ABR | M16: MORNO
A17: BRUNA | B17: São Paulo e Santos | D17: SUPERMERCADO BANDEIRA LTDA | E17: JCP | F17: NOVO | G17: 164443 | H17: 0.25 | I17: 41110.75 | J17: ASSINADO | K17: JAN | L17: ABR | M17: MORNO
A18: BRUNA | B18: São Paulo e Santos | D18: SUPERMERCADO DOS CASA LTDA | E18: IRPJ CSLL | F18: NOVO | G18: 98265 | H18: 0.25 | I18: 24566.25 | J18: ASSINADO | K18: JAN | L18: MAR | M18: QUENTE
A19: BRUNA | B19: São Paulo e Santos | D19: SUPERMERCADOS M FARIA E GRAVINA LTDA | E19: EXCLUSAO DE DESCONTOS DA BASE DO INSS | F19: UPSELL | G19: 327622.89 | H19: 0.18 | I19: 58972.12 | J19: ASSINADO | K19: FEV | L19: FEV | M19: QUENTE
A20: BRUNA | B20: São Paulo e Santos | D20: SUPERMERCADOS M FARIA E GRAVINA LTDA | E20: PREVIDENCIARIO | F20: UPSELL | G20: 181392.16 | H20: 0.18 | I20: 32650.59 | J20: ASSINADO | K20: FEV | L20: FEV | M20: QUENTE
A21: BRUNA | B21: São Paulo e Santos | D21: SUPERMERCADO DOS CASA LTDA | E21: PIS e COFINS | F21: NOVO | G21: 365658 | H21: 0.25 | I21: 91414.5 | J21: ASSINADO | K21: JAN | L21: MAR | M21: QUENTE
A22: CINTHIA | B22: Fortaleza | D22: SUPERMERCADO PRECO IDEAL LTDA | E22: PIS E COFINS INSUMOS | F22: NOVO | G22: 830105 | H22: 0.3 | I22: 249031.5 | J22: STANDBY | K22: FEV | M22: QUENTE
A23: CINTHIA | B23: Fortaleza | D23: SUPER PORTUGAL COMERCIO VAREJISTA LTDA | E23: EXCLUSAO ICMS ST DA BASE PIS COFINS | F23: NOVO | G23: 1818934 | H23: 0.2 | I23: 363786.8 | J23: BASE | K23: ABR
A24: CINTHIA | B24: Fortaleza | D24: SUPER PORTUGAL COMERCIO VAREJISTA LTDA | E24: PIS E COFINS insumos | F24: NOVO | G24: 333845 | H24: 0.2 | I24: 66769 | J24: BASE | K24: ABR
A25: CINTHIA | B25: Fortaleza | D25: SUPERMERCADO LISBOA LTDA | E25: IRPJ E CSLL | F25: NOVO | G25: 643493 | H25: 0.15 | I25: 96523.95 | J25: ASSINADO | K25: MAR | L25: MAR | M25: QUENTE
A26: CINTHIA | B26: Fortaleza | D26: SUPERMERCADO LISBOA LTDA | E26: EXCLUSAO DA BASE ICMS ST DA BASE PIS E CONFINS | F26: NOVO | G26: 1990086 | H26: 0.15 | I26: 298512.9 | J26: ASSINADO | K26: MAR | L26: MAR | M26: QUENTE
A27: CINTHIA | B27: Fortaleza | D27: SUPERMERCADO LISBOA LTDA | E27: PIS E COFINS INSUMOS | F27: NOVO | G27: 190062 | H27: 0.15 | I27: 28509.3 | J27: ASSINADO | K27: MAR | L27: MAR | M27: QUENTE
A28: CINTHIA | B28: Fortaleza | D28: SUPERMERCADO ANALI LTDA | E28: IRPJ E CSLL | F28: NOVO | G28: 530431 | H28: 0.15 | I28: 79564.65 | J28: ASSINADO | K28: MAR | L28: MAR | M28: QUENTE
A29: CINTHIA | B29: Fortaleza | D29: SUPERMERCADO ANALI LTDA | E29: EXCLUSÃO ICMS ST BASE PIS COFINS | F29: NOVO | G29: 2163025 | H29: 0.15 | I29: 324453.75 | J29: ASSINADO | K29: MAR | L29: MAR | M29: QUENTE
A30: CINTHIA | B30: Fortaleza | D30: SUPERMERCADO ANALI LTDA | E30: PIS E COFINS ISUMOS | F30: NOVO | G30: 106730 | H30: 0.15 | I30: 16009.5 | J30: ASSINADO | K30: MAR | L30: MAR | M30: QUENTE
A31: DIMAS | B31: Teresina e Mato Grosso do Sul | D31: F M FERREIRA DE SOUSA LTDA TERESINA | E31: SUBVENÇÃO | F31: NOVO | G31: 1669171 | H31: 0.07 | I31: 116841.97 | J31: ASSINADO | K31: DEZ | L31: DEZ | M31: QUENTE
A32: DIMAS | B32: Teresina e Mato Grosso do Sul | D32: F M FERREIRA DE SOUSA LTDA TERESINA | E32: JCP | F32: NOVO | G32: 174693 | H32: 0.07 | I32: 12228.51 | J32: ASSINADO | K32: DEZ | L32: DEZ | M32: QUENTE
A33: DIMAS | B33: Teresina e Mato Grosso do Sul | D33: F M FERREIRA DE SOUSA LTDA TERESINA | E33: EXCL ICMS ST | F33: NOVO | G33: 1996988 | H33: 0.07 | I33: 139789.16 | J33: ASSINADO | K33: DEZ | L33: DEZ | M33: QUENTE
A34: DIMAS | B34: Teresina e Mato Grosso do Sul | D34: F M FERREIRA DE SOUSA LTDA TERESINA | E34: PREVIDENCIARIO | F34: NOVO | G34: 130125 | H34: 0.06 | I34: 7807.5 | J34: ASSINADO | K34: DEZ | L34: DEZ | M34: QUENTE
A35: DIMAS | B35: Teresina e Mato Grosso do Sul | D35: ESSENCIAL ATACADO LTDA | E35: EXCL ICMS ST | F35: NOVO | G35: 1300203 | H35: 0.15 | I35: 195030.45 | J35: ASSINADO | K35: DEZ | L35: DEZ | M35: QUENTE
A36: DIMAS | B36: Teresina e Mato Grosso do Sul | D36: ESSENCIAL ATACADO LTDA | E36: PIS COFINS | F36: NOVO | G36: 147984 | H36: 0.15 | I36: 29596.8 | J36: ASSINADO | K36: DEZ | L36: DEZ | M36: QUENTE
... A40: DIMAS | B40: Teresina e Mato Grosso do Sul | D40: NANTES & BRITO LTDA COXIM – MS | E40: IRPJ E CSLL | F40: NOVO | G40: 137717 | H40: 0.2 | I40: 27543.4 | J40: ASSINADO | K40: DEZ | L40: DEZ | M40: QUENTE
A41: DIMAS | B41: Teresina e Mato Grosso do Sul | D41: NANTES & BRITO LTDA COXIM – MS | E41: ICMS INSUMOS | F41: NOVO | H41: 0.2 | I41: 0 | J41: ASSINADO | K41: DEZ | L41: DEZ | M41: QUENTE
A42: DIMAS | B42: Teresina e Mato Grosso do Sul | D42: NANTES & BRITO LTDA COXIM – MS | E42: SUBV IRPJ | F42: NOVO | G42: 73540 | H42: 0.2 | I42: 14708 | J42: ASSINADO | K42: DEZ | L42: DEZ | M42: QUENTE
A43: DIMAS | B43: Teresina e Mato Grosso do Sul | D43: HOT SAT INDUSTRIA DE MAQUINAS LTDA | E43: IRPJ CSLL | F43: NOVO | G43: 63506 | H43: 0.18 | I43: 11431.08 | J43: ASSINADO | K43: FEV | L43: FEV | M43: QUENTE
...

Sheet Parâmetros
A1: PARÂMETROS DO DASHBOARD
A3: Mês de referência (1-12) | B3: 4
A4: Dia útil corrente (1-22) | B4: 19
A5: Dias úteis no mês (padrão 22) | B5: 22
A7: Mês de referência (texto) | B7: =INDEX({"JAN","FEV","MAR","ABR","MAI","JUN","JUL","AGO","SET","OUT","NOV","DEZ"},B3)
A9: Como usar:
A10: • Altere B3 para mudar o mês corrente do dashboard
A11: • Altere B4 para refletir o dia útil decorrido (usado na projeção)
A12: • Todos os indicadores se recalculam automaticamente
